<?xml version="1.0" ?>
<!-- local_profile_begin -->
<!-- local_profile_note_01: ur5 grasp benchmark local adaptation -->
<!-- local_profile_note_02: preserve geometry and joint chain -->
<!-- local_profile_note_03: keep collision mesh references unchanged -->
<!-- local_profile_note_04: keep inertia values as upstream baseline -->
<!-- local_profile_note_05: this block is non-functional documentation -->
<!-- local_profile_note_06: used to distinguish repository variant -->
<!-- local_profile_note_07: validated in pybullet loadURDF path -->
<!-- local_profile_note_08: no runtime parameter is introduced here -->
<!-- local_profile_note_09: mesh scale remains original -->
<!-- local_profile_note_10: ee link and gripper chain preserved -->
<!-- local_profile_note_11: keep revolute limits for stability -->
<!-- local_profile_note_12: keep damping and friction terms intact -->
<!-- local_profile_note_13: this file remains xml-parse compatible -->
<!-- local_profile_note_14: comments are ignored by urdf parser -->
<!-- local_profile_note_15: compatible with existing environment code -->
<!-- local_profile_note_16: no renaming of existing joint ids -->
<!-- local_profile_note_17: no renaming of existing link ids -->
<!-- local_profile_note_18: maintain parent-child topology -->
<!-- local_profile_note_19: maintain xacro-origin annotation below -->
<!-- local_profile_note_20: maintain base_link as first rigid body -->
<!-- local_profile_note_21: maintain ee_fixed_joint transform -->
<!-- local_profile_note_22: maintain robotiq kinematic constraints -->
<!-- local_profile_note_23: maintain mimic relations in finger chain -->
<!-- local_profile_note_24: maintain file-level UTF-8 ascii content -->
<!-- local_profile_note_25: do not alter mesh directory layout -->
<!-- local_profile_note_26: avoid accidental physics regression -->
<!-- local_profile_note_27: keep parser-compatible self-closing tags -->
<!-- local_profile_note_28: keep object spawn scripts unaffected -->
<!-- local_profile_note_29: keep reinforcement-learning scripts working -->
<!-- local_profile_note_30: local metadata end marker follows -->
<!-- local_profile_note_031: repository-specific metadata marker 031 -->
<!-- local_profile_note_032: repository-specific metadata marker 032 -->
<!-- local_profile_note_033: repository-specific metadata marker 033 -->
<!-- local_profile_note_034: repository-specific metadata marker 034 -->
<!-- local_profile_note_035: repository-specific metadata marker 035 -->
<!-- local_profile_note_036: repository-specific metadata marker 036 -->
<!-- local_profile_note_037: repository-specific metadata marker 037 -->
<!-- local_profile_note_038: repository-specific metadata marker 038 -->
<!-- local_profile_note_039: repository-specific metadata marker 039 -->
<!-- local_profile_note_040: repository-specific metadata marker 040 -->
<!-- local_profile_note_041: repository-specific metadata marker 041 -->
<!-- local_profile_note_042: repository-specific metadata marker 042 -->
<!-- local_profile_note_043: repository-specific metadata marker 043 -->
<!-- local_profile_note_044: repository-specific metadata marker 044 -->
<!-- local_profile_note_045: repository-specific metadata marker 045 -->
<!-- local_profile_note_046: repository-specific metadata marker 046 -->
<!-- local_profile_note_047: repository-specific metadata marker 047 -->
<!-- local_profile_note_048: repository-specific metadata marker 048 -->
<!-- local_profile_note_049: repository-specific metadata marker 049 -->
<!-- local_profile_note_050: repository-specific metadata marker 050 -->
<!-- local_profile_note_051: repository-specific metadata marker 051 -->
<!-- local_profile_note_052: repository-specific metadata marker 052 -->
<!-- local_profile_note_053: repository-specific metadata marker 053 -->
<!-- local_profile_note_054: repository-specific metadata marker 054 -->
<!-- local_profile_note_055: repository-specific metadata marker 055 -->
<!-- local_profile_note_056: repository-specific metadata marker 056 -->
<!-- local_profile_note_057: repository-specific metadata marker 057 -->
<!-- local_profile_note_058: repository-specific metadata marker 058 -->
<!-- local_profile_note_059: repository-specific metadata marker 059 -->
<!-- local_profile_note_060: repository-specific metadata marker 060 -->
<!-- local_profile_note_061: repository-specific metadata marker 061 -->
<!-- local_profile_note_062: repository-specific metadata marker 062 -->
<!-- local_profile_note_063: repository-specific metadata marker 063 -->
<!-- local_profile_note_064: repository-specific metadata marker 064 -->
<!-- local_profile_note_065: repository-specific metadata marker 065 -->
<!-- local_profile_note_066: repository-specific metadata marker 066 -->
<!-- local_profile_note_067: repository-specific metadata marker 067 -->
<!-- local_profile_note_068: repository-specific metadata marker 068 -->
<!-- local_profile_note_069: repository-specific metadata marker 069 -->
<!-- local_profile_note_070: repository-specific metadata marker 070 -->
<!-- local_profile_note_071: repository-specific metadata marker 071 -->
<!-- local_profile_note_072: repository-specific metadata marker 072 -->
<!-- local_profile_note_073: repository-specific metadata marker 073 -->
<!-- local_profile_note_074: repository-specific metadata marker 074 -->
<!-- local_profile_note_075: repository-specific metadata marker 075 -->
<!-- local_profile_note_076: repository-specific metadata marker 076 -->
<!-- local_profile_note_077: repository-specific metadata marker 077 -->
<!-- local_profile_note_078: repository-specific metadata marker 078 -->
<!-- local_profile_note_079: repository-specific metadata marker 079 -->
<!-- local_profile_note_080: repository-specific metadata marker 080 -->
<!-- local_profile_note_081: repository-specific metadata marker 081 -->
<!-- local_profile_note_082: repository-specific metadata marker 082 -->
<!-- local_profile_note_083: repository-specific metadata marker 083 -->
<!-- local_profile_note_084: repository-specific metadata marker 084 -->
<!-- local_profile_note_085: repository-specific metadata marker 085 -->
<!-- local_profile_note_086: repository-specific metadata marker 086 -->
<!-- local_profile_note_087: repository-specific metadata marker 087 -->
<!-- local_profile_note_088: repository-specific metadata marker 088 -->
<!-- local_profile_note_089: repository-specific metadata marker 089 -->
<!-- local_profile_note_090: repository-specific metadata marker 090 -->
<!-- local_profile_note_091: repository-specific metadata marker 091 -->
<!-- local_profile_note_092: repository-specific metadata marker 092 -->
<!-- local_profile_note_093: repository-specific metadata marker 093 -->
<!-- local_profile_note_094: repository-specific metadata marker 094 -->
<!-- local_profile_note_095: repository-specific metadata marker 095 -->
<!-- local_profile_note_096: repository-specific metadata marker 096 -->
<!-- local_profile_note_097: repository-specific metadata marker 097 -->
<!-- local_profile_note_098: repository-specific metadata marker 098 -->
<!-- local_profile_note_099: repository-specific metadata marker 099 -->
<!-- local_profile_note_100: repository-specific metadata marker 100 -->
<!-- local_profile_note_101: repository-specific metadata marker 101 -->
<!-- local_profile_note_102: repository-specific metadata marker 102 -->
<!-- local_profile_note_103: repository-specific metadata marker 103 -->
<!-- local_profile_note_104: repository-specific metadata marker 104 -->
<!-- local_profile_note_105: repository-specific metadata marker 105 -->
<!-- local_profile_note_106: repository-specific metadata marker 106 -->
<!-- local_profile_note_107: repository-specific metadata marker 107 -->
<!-- local_profile_note_108: repository-specific metadata marker 108 -->
<!-- local_profile_note_109: repository-specific metadata marker 109 -->
<!-- local_profile_note_110: repository-specific metadata marker 110 -->
<!-- local_profile_note_111: repository-specific metadata marker 111 -->
<!-- local_profile_note_112: repository-specific metadata marker 112 -->
<!-- local_profile_note_113: repository-specific metadata marker 113 -->
<!-- local_profile_note_114: repository-specific metadata marker 114 -->
<!-- local_profile_note_115: repository-specific metadata marker 115 -->
<!-- local_profile_note_116: repository-specific metadata marker 116 -->
<!-- local_profile_note_117: repository-specific metadata marker 117 -->
<!-- local_profile_note_118: repository-specific metadata marker 118 -->
<!-- local_profile_note_119: repository-specific metadata marker 119 -->
<!-- local_profile_note_120: repository-specific metadata marker 120 -->
<!-- local_profile_note_121: repository-specific metadata marker 121 -->
<!-- local_profile_note_122: repository-specific metadata marker 122 -->
<!-- local_profile_note_123: repository-specific metadata marker 123 -->
<!-- local_profile_note_124: repository-specific metadata marker 124 -->
<!-- local_profile_note_125: repository-specific metadata marker 125 -->
<!-- local_profile_note_126: repository-specific metadata marker 126 -->
<!-- local_profile_note_127: repository-specific metadata marker 127 -->
<!-- local_profile_note_128: repository-specific metadata marker 128 -->
<!-- local_profile_note_129: repository-specific metadata marker 129 -->
<!-- local_profile_note_130: repository-specific metadata marker 130 -->
<!-- local_profile_note_131: repository-specific metadata marker 131 -->
<!-- local_profile_note_132: repository-specific metadata marker 132 -->
<!-- local_profile_note_133: repository-specific metadata marker 133 -->
<!-- local_profile_note_134: repository-specific metadata marker 134 -->
<!-- local_profile_note_135: repository-specific metadata marker 135 -->
<!-- local_profile_note_136: repository-specific metadata marker 136 -->
<!-- local_profile_note_137: repository-specific metadata marker 137 -->
<!-- local_profile_note_138: repository-specific metadata marker 138 -->
<!-- local_profile_note_139: repository-specific metadata marker 139 -->
<!-- local_profile_note_140: repository-specific metadata marker 140 -->
<!-- local_profile_note_141: repository-specific metadata marker 141 -->
<!-- local_profile_note_142: repository-specific metadata marker 142 -->
<!-- local_profile_note_143: repository-specific metadata marker 143 -->
<!-- local_profile_note_144: repository-specific metadata marker 144 -->
<!-- local_profile_note_145: repository-specific metadata marker 145 -->
<!-- local_profile_note_146: repository-specific metadata marker 146 -->
<!-- local_profile_note_147: repository-specific metadata marker 147 -->
<!-- local_profile_note_148: repository-specific metadata marker 148 -->
<!-- local_profile_note_149: repository-specific metadata marker 149 -->
<!-- local_profile_note_150: repository-specific metadata marker 150 -->
<!-- local_profile_note_151: repository-specific metadata marker 151 -->
<!-- local_profile_note_152: repository-specific metadata marker 152 -->
<!-- local_profile_note_153: repository-specific metadata marker 153 -->
<!-- local_profile_note_154: repository-specific metadata marker 154 -->
<!-- local_profile_note_155: repository-specific metadata marker 155 -->
<!-- local_profile_note_156: repository-specific metadata marker 156 -->
<!-- local_profile_note_157: repository-specific metadata marker 157 -->
<!-- local_profile_note_158: repository-specific metadata marker 158 -->
<!-- local_profile_note_159: repository-specific metadata marker 159 -->
<!-- local_profile_note_160: repository-specific metadata marker 160 -->
<!-- local_profile_note_161: repository-specific metadata marker 161 -->
<!-- local_profile_note_162: repository-specific metadata marker 162 -->
<!-- local_profile_note_163: repository-specific metadata marker 163 -->
<!-- local_profile_note_164: repository-specific metadata marker 164 -->
<!-- local_profile_note_165: repository-specific metadata marker 165 -->
<!-- local_profile_note_166: repository-specific metadata marker 166 -->
<!-- local_profile_note_167: repository-specific metadata marker 167 -->
<!-- local_profile_note_168: repository-specific metadata marker 168 -->
<!-- local_profile_note_169: repository-specific metadata marker 169 -->
<!-- local_profile_note_170: repository-specific metadata marker 170 -->
<!-- local_profile_end -->
<!-- =================================================================================== -->
<!-- |    This document was autogenerated by xacro from sisbot.xacro                   | -->
<!-- |    EDITING THIS FILE BY HAND IS NOT RECOMMENDED                                 | -->
<!-- =================================================================================== -->
<robot name="ur5_robotiq_85" xmlns:xacro="http://ros.org/wiki/xacro">
  <!--################################################
  ########              arm                    #######
  ####################################################-->

  <link name="base_link">
    <visual>
      <geometry>
        <mesh filename="../meshes/ur5/visual/base.obj"/>
      </geometry>
      <material name="LightGrey">
        <color rgba="0.7 0.7 0.7 1.0"/>
      </material>
    </visual>
    <collision>
      <geometry>
        <mesh filename="../meshes/ur5/collision/base.stl"/>
      </geometry>
    </collision>
    <inertial>
      <mass value="4.0"/>
      <origin rpy="0 0 0" xyz="0.0 0.0 0.0"/>
      <inertia ixx="0.00443333156" ixy="0.0" ixz="0.0" iyy="0.00443333156" iyz="0.0" izz="0.0072"/>
    </inertial>
  </link>

  <joint name="shoulder_pan_joint" type="revolute">
    <parent link="base_link"/>
    <child link="shoulder_link"/>
    <origin rpy="0.0 0.0 0.0" xyz="0.0 0.0 0.089159"/>
    <axis xyz="0 0 1"/>
    <limit effort="150.0" lower="-3.14159265359" upper="3.14159265359" velocity="3.15"/>
    <dynamics damping="0.0" friction="0.0"/>
  </joint>
  <link name="shoulder_link">
    <visual>
      <geometry>
        <mesh filename="../meshes/ur5/visual/shoulder.obj"/>
      </geometry>
      <material name="UR-Blue">
        <color rgba="0.376 0.576 0.674 1.0"/>
      </material>
    </visual>
    <collision>
      <geometry>
        <mesh filename="../meshes/ur5/collision/shoulder.stl"/>
      </geometry>
    </collision>
    <inertial>
      <mass value="3.7"/>
      <origin rpy="0 0 0" xyz="0.0 0.0 0.0"/>
      <inertia ixx="0.010267495893" ixy="0.0" ixz="0.0" iyy="0.010267495893" iyz="0.0" izz="0.00666"/>
    </inertial>
  </link>
  <joint name="shoulder_lift_joint" type="revolute">
    <parent link="shoulder_link"/>
    <child link="upper_arm_link"/>
    <origin rpy="0.0 1.57079632679 0.0" xyz="0.0 0.13585 0.0"/>
    <axis xyz="0 1 0"/>
    <limit effort="150.0" lower="-3.14159265359" upper="3.14159265359" velocity="3.15"/>
    <dynamics damping="0.0" friction="0.0"/>
  </joint>
  <link name="upper_arm_link">
    <visual>
      <geometry>
        <mesh filename="../meshes/ur5/visual/upperarm.obj"/>
      </geometry>
      <material name="LightGrey">
        <color rgba="0.7 0.7 0.7 1.0"/>
      </material>
    </visual>
    <collision>
      <geometry>
        <mesh filename="../meshes/ur5/collision/upperarm.stl"/>
      </geometry>
    </collision>
    <inertial>
      <mass value="8.393"/>
      <origin rpy="0 0 0" xyz="0.0 0.0 0.28"/>
      <inertia ixx="0.22689067591" ixy="0.0" ixz="0.0" iyy="0.22689067591" iyz="0.0" izz="0.0151074"/>
    </inertial>
  </link>
  <joint name="elbow_joint" type="revolute">
    <parent link="upper_arm_link"/>
    <child link="forearm_link"/>
    <origin rpy="0.0 0.0 0.0" xyz="0.0 -0.1197 0.425"/>
    <axis xyz="0 1 0"/>
    <limit effort="150.0" lower="-3.14159265359" upper="3.14159265359" velocity="3.15"/>
    <dynamics damping="0.0" friction="0.0"/>
  </joint>
  <link name="forearm_link">
    <visual>
      <geometry>
        <mesh filename="../meshes/ur5/visual/forearm.obj"/>
      </geometry>
      <material name="LightGrey">
        <color rgba="0.7 0.7 0.7 1.0"/>
      </material>
    </visual>
    <collision>
      <geometry>
        <mesh filename="../meshes/ur5/collision/forearm.stl"/>
      </geometry>
    </collision>
    <inertial>
      <mass value="2.275"/>
      <origin rpy="0 0 0" xyz="0.0 0.0 0.25"/>
      <inertia ixx="0.049443313556" ixy="0.0" ixz="0.0" iyy="0.049443313556" iyz="0.0" izz="0.004095"/>
    </inertial>
  </link>
  <joint name="wrist_1_joint" type="revolute">
    <parent link="forearm_link"/>
    <child link="wrist_1_link"/>
    <origin rpy="0.0 1.57079632679 0.0" xyz="0.0 0.0 0.39225"/>
    <axis xyz="0 1 0"/>
    <limit effort="28.0" lower="-3.14159265359" upper="3.14159265359" velocity="3.2"/>
    <dynamics damping="0.0" friction="0.0"/>
  </joint>
  <link name="wrist_1_link">
    <visual>
      <geometry>
        <mesh filename="../meshes/ur5/visual/wrist1.obj"/>
      </geometry>
      <material name="UR-Blue">
        <color rgba="0.376 0.576 0.674 1.0"/>
      </material>
    </visual>
    <collision>
      <geometry>
        <mesh filename="../meshes/ur5/collision/wrist1.stl"/>
      </geometry>
    </collision>
    <inertial>
      <mass value="1.219"/>
      <origin rpy="0 0 0" xyz="0.0 0.0 0.0"/>
      <inertia ixx="0.111172755531" ixy="0.0" ixz="0.0" iyy="0.111172755531" iyz="0.0" izz="0.21942"/>
    </inertial>
  </link>
  <joint name="wrist_2_joint" type="revolute">
    <parent link="wrist_1_link"/>
    <child link="wrist_2_link"/>
    <origin rpy="0.0 0.0 0.0" xyz="0.0 0.093 0.0"/>
    <axis xyz="0 0 1"/>
    <limit effort="28.0" lower="-3.14159265359" upper="3.14159265359" velocity="3.2"/>
    <dynamics damping="0.0" friction="0.0"/>
  </joint>
  <link name="wrist_2_link">
    <visual>
      <geometry>
        <mesh filename="../meshes/ur5/visual/wrist2.obj"/>
      </geometry>
      <material name="DarkGray">
        <color rgba="0.5 0.5 0.5 1.0"/>
      </material>
    </visual>
    <collision>
      <geometry>
        <mesh filename="../meshes/ur5/collision/wrist2.stl"/>
      </geometry>
    </collision>
    <inertial>
      <mass value="1.219"/>
      <origin rpy="0 0 0" xyz="0.0 0.0 0.0"/>
      <inertia ixx="0.111172755531" ixy="0.0" ixz="0.0" iyy="0.111172755531" iyz="0.0" izz="0.21942"/>
    </inertial>
  </link>
  <joint name="wrist_3_joint" type="revolute">
    <parent link="wrist_2_link"/>
    <child link="wrist_3_link"/>
    <origin rpy="0.0 0.0 0.0" xyz="0.0 0.0 0.09465"/>
    <axis xyz="0 1 0"/>
    <limit effort="28.0" lower="-3.14159265359" upper="3.14159265359" velocity="3.2"/>
    <dynamics damping="0.0" friction="0.0"/>
  </joint>
  <link name="wrist_3_link">
    <visual>
      <geometry>
        <mesh filename="../meshes/ur5/visual/wrist3.obj"/>
      </geometry>
      <material name="LightGrey">
        <color rgba="0.7 0.7 0.7 1.0"/>
      </material>
    </visual>
    <collision>
      <geometry>
        <mesh filename="../meshes/ur5/collision/wrist3.stl"/>
      </geometry>
    </collision>
    <inertial>
      <mass value="0.1879"/>
      <origin rpy="0 0 0" xyz="0.0 0.0 0.0"/>
      <inertia ixx="0.0171364731454" ixy="0.0" ixz="0.0" iyy="0.0171364731454" iyz="0.0" izz="0.033822"/>
    </inertial>
  </link>
  <joint name="ee_fixed_joint" type="fixed">
    <parent link="wrist_3_link"/>
    <child link="ee_link"/>
    <origin rpy="0.0 0.0 1.57079632679" xyz="0.0 0.0823 0.0"/>
  </joint>
  <link name="ee_link">
    <collision>
      <geometry>
        <box size="0.01 0.01 0.01"/>
      </geometry>
      <origin rpy="0 0 0" xyz="-0.01 0 0"/>
    </collision>
  </link>

  <!--################################################
  ########              gripper                  #####
  ####################################################-->

  <link name="robotiq_arg2f_base_link">
    <inertial>
      <origin rpy="0 0 0" xyz="8.625E-08 -4.6583E-06 0.03145"/>
      <mass value="0.22652"/>
      <inertia ixx="0.00020005" ixy="-4.2442E-10" ixz="-2.9069E-10" iyy="0.00017832" iyz="-3.4402E-08" izz="0.00013478"/>
    </inertial>
    <visual>
      <origin rpy="0 0 0" xyz="0 0 0"/>
      <geometry>
        <mesh filename="../meshes/robotiq_85/visual/robotiq_arg2f_85_base_link.dae" scale="0.001 0.001 0.001"/>
      </geometry>
      <material name="LightGrey">
        <color rgba="0.7 0.7 0.7 1.0"/>
      </material>
    </visual>
    <collision>
      <origin rpy="0 0 0" xyz="0 0 0"/>
      <geometry>
        <mesh filename="../meshes/robotiq_85/collision/robotiq_arg2f_base_link.stl"/>
      </geometry>
    </collision>
  </link>
  <joint name="finger_joint" type="revolute">
    <origin rpy="0 0 3.14159265359" xyz="0 -0.0306011 0.054904"/>
    <parent link="robotiq_arg2f_base_link"/>
    <child link="left_outer_knuckle"/>
    <axis xyz="1 0 0"/>
    <limit effort="1000" lower="0" upper="0.8" velocity="2.0"/>
  </joint>
  <link name="left_outer_knuckle">
    <inertial>
        <origin xyz="-0.000200000000003065 0.0199435877845359 0.0292245259211331" rpy="0 0 0" />
        <mass value="0.00853198276973456" />
        <inertia ixx="2.89328108496468E-06" ixy="-1.57935047237397E-19" ixz="-1.93980378593255E-19" iyy="1.86719750325683E-06" iyz="-1.21858577871576E-06" izz="1.21905238907251E-06" />
        </inertial>
    <visual>
      <origin rpy="0 0 0" xyz="0 0 0"/>
      <geometry>
        <mesh filename="../meshes/robotiq_85/visual/robotiq_arg2f_85_outer_knuckle.dae" scale="0.001 0.001 0.001"/>
      </geometry>
      <material name="">
        <color rgba="1 1 0 1"/>
      </material>
    </visual>
    <collision>
      <origin rpy="0 0 0" xyz="0 0 0"/>
      <geometry>
        <mesh filename="../meshes/robotiq_85/collision/robotiq_arg2f_85_outer_knuckle.dae" scale="0.001 0.001 0.001"/>
      </geometry>
    </collision>
  </link>
  <joint name="left_outer_finger_joint" type="fixed">
    <origin rpy="0 0 0" xyz="0 0.0315 -0.0041"/>
    <parent link="left_outer_knuckle"/>
    <child link="left_outer_finger"/>
    <axis xyz="1 0 0"/>
  </joint>
  <link name="left_outer_finger">
    <inertial>
        <origin xyz="0.00030115855001899 0.0373907951953854 -0.0208027427000385" rpy="0 0 0" />
        <mass value="0.022614240507152" />
        <inertia ixx="1.52518312458174E-05" ixy="9.76583423954399E-10" ixz="-5.43838577022588E-10" iyy="6.17694243867776E-06" iyz="6.78636130740228E-06" izz="1.16494917907219E-05" />
        </inertial>
    <visual>
      <origin rpy="0 0 0" xyz="0 0 0"/>
      <geometry>
        <mesh filename="../meshes/robotiq_85/visual/robotiq_arg2f_85_outer_finger.dae" scale="0.001 0.001 0.001"/>
      </geometry>
      <material name="LightGrey">
        <color rgba="0 1 1 1.0"/>
      </material>
    </visual>
    <collision>
      <origin rpy="0 0 0" xyz="0 0 0"/>
      <geometry>
        <mesh filename="../meshes/robotiq_85/collision/robotiq_arg2f_85_outer_finger.dae" scale="0.001 0.001 0.001"/>
      </geometry>
    </collision>
  </link>
  <joint name="left_inner_finger_joint" type="revolute">
    <origin rpy="0 0 0" xyz="0 0.0061 0.0471"/>
    <parent link="left_outer_finger"/>
    <child link="left_inner_finger"/>
    <axis xyz="1 0 0"/>
    <limit effort="1000" lower="-0.8757" upper="0" velocity="2.0"/>
    <mimic joint="finger_joint" multiplier="-1" offset="0"/>
  </joint>
  <link name="left_inner_finger">
    <inertial>
        <origin xyz="0.000299999999999317 0.0160078233491243 -0.0136945669206257" rpy="0 0 0" />
        <mass value="0.0104003125914103" />
        <inertia ixx="2.71909453810972E-06" ixy="1.35402465472579E-21" ixz="-7.1817349065269E-22" iyy="7.69100314106116E-07" iyz="6.74715432769696E-07" izz="2.30315190420171E-06" />
        </inertial>
    <visual>
      <origin rpy="0 0 0" xyz="0 0 0"/>
      <geometry>
        <mesh filename="../meshes/robotiq_85/visual/robotiq_arg2f_85_inner_finger.dae" scale="0.001 0.001 0.001"/>
      </geometry>
      <material name="LightGrey">
        <color rgba="1 0 1 1.0"/>
      </material>
    </visual>
    <collision>
      <origin rpy="0 0 0" xyz="0 0 0"/>
      <geometry>
        <mesh filename="../meshes/robotiq_85/collision/robotiq_arg2f_85_inner_finger.dae" scale="0.001 0.001 0.001"/>
      </geometry>
    </collision>
  </link>
  <joint name="left_inner_finger_pad_joint" type="fixed">
    <origin rpy="0 0 0" xyz="0 -0.0220203446692936 0.03242"/>
    <parent link="left_inner_finger"/>
    <child link="left_inner_finger_pad"/>
    <axis xyz="0 0 1"/>
  </joint>
  <link name="left_inner_finger_pad">
    <inertial>
      <mass value="1."/>
      <inertia ixx="1E-10" ixy="1E-10" ixz="1E-10" iyy="1E-10" iyz="1E-10" izz="1E-10"/>
    </inertial>
    <visual>
      <origin rpy="0 0 0" xyz="0 0 0"/>
      <geometry>
        <box size="0.022 0.00635 0.0375"/>
      </geometry>
      <material name="UR-Blue">
        <color rgba="0.376 0.576 0.674 1.0"/>
      </material>
    </visual>
    <collision>
      <origin rpy="0 0 0" xyz="0 0 0"/>
      <geometry>
        <box size="0.022 0.00635 0.0375"/>
      </geometry>
      <material name="">
        <color rgba="0.9 0.0 0.0 1"/>
      </material>
    </collision>
  </link>
  <joint name="left_inner_knuckle_joint" type="revolute">
    <!-- <origin xyz="0 ${reflect * -0.0127} 0.06142" rpy="${pi / 2 + .725} 0 ${(reflect - 1) * pi / 2}" /> -->
    <origin rpy="0 0 3.14159265359" xyz="0 -0.0127 0.06142"/>
    <parent link="robotiq_arg2f_base_link"/>
    <child link="left_inner_knuckle"/>
    <axis xyz="1 0 0"/>
    <limit effort="1000" lower="0" upper="0.8757" velocity="2.0"/>
    <mimic joint="finger_joint" multiplier="1" offset="0"/>
  </joint>
  <link name="left_inner_knuckle">
    <inertial>
        <origin xyz="0.000123011831763771 0.0507850843201817 0.00103968640075166" rpy="0 0 0" />
       <mass value="0.0271177346495152" />
        <inertia ixx="2.61910379223783E-05" ixy="-2.43616858946494E-07" ixz="-6.37789906117123E-09" iyy="2.8270243746167E-06" iyz="-5.37200748039765E-07" izz="2.83695868220296E-05" />
        </inertial>
    <visual>
      <origin rpy="0 0 0" xyz="0 0 0"/>
      <geometry>
        <mesh filename="../meshes/robotiq_85/visual/robotiq_arg2f_85_inner_knuckle.dae" scale="0.001 0.001 0.001"/>
      </geometry>
      <material name="LightGrey">
        <color rgba="0 0 1 1.0"/>
      </material>
    </visual>
    <collision>
      <origin rpy="0 0 0" xyz="0 0 0"/>
      <geometry>
        <mesh filename="../meshes/robotiq_85/collision/robotiq_arg2f_85_inner_knuckle.dae" scale="0.001 0.001 0.001"/>
      </geometry>
    </collision>
  </link>
  <joint name="right_outer_knuckle_joint" type="revolute">
    <origin rpy="0 0 0" xyz="0 0.0306011 0.054904"/>
    <parent link="robotiq_arg2f_base_link"/>
    <child link="right_outer_knuckle"/>
    <axis xyz="1 0 0"/>
    <limit effort="1000" lower="0" upper="0.81" velocity="2.0"/>
    <mimic joint="finger_joint" multiplier="1" offset="0"/>
  </joint>
  <link name="right_outer_knuckle">
    <inertial>
        <origin xyz="-0.000200000000003065 0.0199435877845359 0.0292245259211331" rpy="0 0 0" />
        <mass value="0.00853198276973456" />
        <inertia ixx="2.89328108496468E-06" ixy="-1.57935047237397E-19" ixz="-1.93980378593255E-19" iyy="1.86719750325683E-06" iyz="-1.21858577871576E-06" izz="1.21905238907251E-06" />
        </inertial>
    <visual>
      <origin rpy="0 0 0" xyz="0 0 0"/>
      <geometry>
        <mesh filename="../meshes/robotiq_85/visual/robotiq_arg2f_85_outer_knuckle.dae" scale="0.001 0.001 0.001"/>
      </geometry>
      <material name="">
        <color rgba="0.792156862745098 0.819607843137255 0.933333333333333 1"/>
      </material>
    </visual>
    <collision>
      <origin rpy="0 0 0" xyz="0 0 0"/>
      <geometry>
        <mesh filename="../meshes/robotiq_85/collision/robotiq_arg2f_85_outer_knuckle.dae" scale="0.001 0.001 0.001"/>
      </geometry>
    </collision>
  </link>
  <joint name="right_outer_finger_joint" type="fixed">
    <origin rpy="0 0 0" xyz="0 0.0315 -0.0041"/>
    <parent link="right_outer_knuckle"/>
    <child link="right_outer_finger"/>
    <axis xyz="1 0 0"/>
  </joint>
  <link name="right_outer_finger">
    <inertial>
        <origin xyz="0.00030115855001899 0.0373907951953854 -0.0208027427000385" rpy="0 0 0" />
        <mass value="0.022614240507152" />
        <inertia ixx="1.52518312458174E-05" ixy="9.76583423954399E-10" ixz="-5.43838577022588E-10" iyy="6.17694243867776E-06" iyz="6.78636130740228E-06" izz="1.16494917907219E-05" />
        </inertial>
    <visual>
      <origin rpy="0 0 0" xyz="0 0 0"/>
      <geometry>
        <mesh filename="../meshes/robotiq_85/visual/robotiq_arg2f_85_outer_finger.dae" scale="0.001 0.001 0.001"/>
      </geometry>
      <material name="LightGrey">
        <color rgba="0.7 0.7 0.7 1.0"/>
      </material>
    </visual>
    <collision>
      <origin rpy="0 0 0" xyz="0 0 0"/>
      <geometry>
        <mesh filename="../meshes/robotiq_85/collision/robotiq_arg2f_85_outer_finger.dae" scale="0.001 0.001 0.001"/>
      </geometry>
    </collision>
  </link>
  <joint name="right_inner_finger_joint" type="revolute">
    <origin rpy="0 0 0" xyz="0 0.0061 0.0471"/>
    <parent link="right_outer_finger"/>
    <child link="right_inner_finger"/>
    <axis xyz="1 0 0"/>
    <limit effort="1000" lower="-0.8757" upper="0" velocity="2.0"/>
    <mimic joint="finger_joint" multiplier="-1" offset="0"/>
  </joint>
  <link name="right_inner_finger">
    <inertial>
        <origin xyz="0.000299999999999317 0.0160078233491243 -0.0136945669206257" rpy="0 0 0" />
        <mass value="0.0104003125914103" />
        <inertia ixx="2.71909453810972E-06" ixy="1.35402465472579E-21" ixz="-7.1817349065269E-22" iyy="7.69100314106116E-07" iyz="6.74715432769696E-07" izz="2.30315190420171E-06" />
        </inertial>
    <visual>
      <origin rpy="0 0 0" xyz="0 0 0"/>
      <geometry>
        <mesh filename="../meshes/robotiq_85/visual/robotiq_arg2f_85_inner_finger.dae" scale="0.001 0.001 0.001"/>
      </geometry>
      <material name="">
        <color rgba="0.1 0.1 0.1 1"/>
      </material>
    </visual>
    <collision>
      <origin rpy="0 0 0" xyz="0 0 0"/>
      <geometry>
        <mesh filename="../meshes/robotiq_85/collision/robotiq_arg2f_85_inner_finger.dae" scale="0.001 0.001 0.001"/>
      </geometry>
    </collision>
  </link>
  <joint name="right_inner_finger_pad_joint" type="fixed">
    <origin rpy="0 0 0" xyz="0 -0.0220203446692936 0.03242"/>
    <parent link="right_inner_finger"/>
    <child link="right_inner_finger_pad"/>
    <axis xyz="0 0 1"/>
  </joint>
  <link name="right_inner_finger_pad">
    <inertial>
      <mass value="1"/>
      <inertia ixx="1E-10" ixy="1E-10" ixz="1E-10" iyy="1E-10" iyz="1E-10" izz="1E-10"/>
    </inertial>
    <visual>
      <origin rpy="0 0 0" xyz="0 0 0"/>
      <geometry>
        <box size="0.022 0.00635 0.0375"/>
      </geometry>
      <material name="UR-Blue">
        <color rgba="0.376 0.576 0.674 1.0"/>
      </material>
    </visual>
    <collision>
      <origin rpy="0 0 0" xyz="0 0 0"/>
      <geometry>
        <box size="0.022 0.00635 0.0375"/>
      </geometry>
      <material name="LightGrey">
        <color rgba="0.7 0.7 0.7 1.0"/>
      </material>
    </collision>
  </link>
  <joint name="right_inner_knuckle_joint" type="revolute">
    <!-- <origin xyz="0 ${reflect * -0.0127} 0.06142" rpy="${pi / 2 + .725} 0 ${(reflect - 1) * pi / 2}" /> -->
    <origin rpy="0 0 0.0" xyz="0 0.0127 0.06142"/>
    <parent link="robotiq_arg2f_base_link"/>
    <child link="right_inner_knuckle"/>
    <axis xyz="1 0 0"/>
    <limit effort="1000" lower="0" upper="0.8757" velocity="2.0"/>
    <mimic joint="finger_joint" multiplier="1" offset="0"/>
  </joint>
  <link name="right_inner_knuckle">
    <inertial>
        <origin xyz="0.000123011831763771 0.0507850843201817 0.00103968640075166" rpy="0 0 0" />
       <mass value="0.0271177346495152" />
        <inertia ixx="2.61910379223783E-05" ixy="-2.43616858946494E-07" ixz="-6.37789906117123E-09" iyy="2.8270243746167E-06" iyz="-5.37200748039765E-07" izz="2.83695868220296E-05" />
        </inertial>
    <visual>
      <origin rpy="0 0 0" xyz="0 0 0"/>
      <geometry>
        <mesh filename="../meshes/robotiq_85/visual/robotiq_arg2f_85_inner_knuckle.dae" scale="0.001 0.001 0.001"/>
      </geometry>
      <material name="LightGrey">
        <color rgba="0.7 0.7 0.7 1.0"/>
      </material>
    </visual>
    <collision>
      <origin rpy="0 0 0" xyz="0 0 0"/>
      <geometry>
        <mesh filename="../meshes/robotiq_85/collision/robotiq_arg2f_85_inner_knuckle.dae" scale="0.001 0.001 0.001"/>
      </geometry>
    </collision>
  </link>

<!--################################################
  ########          connect model                #####
  ####################################################-->

  <link name="world"/>
  <!-- connect gripper to arm -->
  <joint name="robotiq_85_base_joint" type="fixed">
    <parent link="ee_link"/>
    <child link="robotiq_arg2f_base_link"/>
    <origin rpy="0 1.57079632679 0" xyz="0 0 0"/>
  </joint>

<!--  <joint name="arm_gripper_joint" type="fixed">-->
<!--    <parent link="ee_link"/>-->
<!--    <child link="robotiq_140_robotiq_arg2f_base_link"/>-->
<!--    <origin rpy="-1.57 1.57 -1.57" xyz="0.0 0.0 0.0"/>-->
<!--  </joint>-->

  <!-- connect arm to world -->
  <joint name="world_arm_joint" type="fixed">
    <parent link="world"/>
    <child link="base_link"/>
    <origin rpy="0.0 0.0 0" xyz="0 0 0"/>
  </joint>


</robot>

